2025-08-17 16:18:46 - INFO - Snowflake Connector for Python Version: 3.17.1, Python Version: 3.13.7, Platform: Windows-11-10.0.26100-SP0
2025-08-17 16:18:46 - INFO - Connecting to GLOBAL Snowflake domain
2025-08-17 16:18:46 - WARNING - Retrying (Retry(total=0, connect=None, read=None, redirect=None, status=None)) after connection broken by 'NewConnectionError('<snowflake.connector.vendored.urllib3.connection.HTTPConnection object at 0x0000015B6005EC10>: Failed to establish a new connection: [Errno 11001] getaddrinfo failed')': /
2025-08-17 16:18:46 - WARNING - Retrying (Retry(total=0, connect=None, read=None, redirect=None, status=None)) after connection broken by 'NewConnectionError('<snowflake.connector.vendored.urllib3.connection.HTTPConnection object at 0x0000015B60032EA0>: Failed to establish a new connection: [Errno 11001] getaddrinfo failed')': /computeMetadata/v1/instance/service-accounts/default/email
2025-08-17 16:18:46 - WARNING - Retrying (Retry(total=0, connect=None, read=None, redirect=None, status=None)) after connection broken by 'ConnectTimeoutError(<snowflake.connector.vendored.urllib3.connection.HTTPConnection object at 0x0000015B6006DFD0>, 'Connection to 169.254.169.254 timed out. (connect timeout=0.2)')': /metadata/instance?api-version=2021-02-01
2025-08-17 16:18:46 - WARNING - Retrying (Retry(total=0, connect=None, read=None, redirect=None, status=None)) after connection broken by 'ConnectTimeoutError(<snowflake.connector.vendored.urllib3.connection.HTTPConnection object at 0x0000015B6005E850>, 'Connection to 169.254.169.254 timed out. (connect timeout=0.2)')': /metadata/identity/oauth2/token?api-version=2018-02-01&resource=https://management.azure.com
2025-08-17 16:18:54 - INFO - Uploaded 1000 rows to 'customer_churn' in Snowflake.
2025-08-17 16:18:54 - INFO - Synthetic customer churn data generated successfully.
