2025-08-22 10:11:43 - INFO - Snowflake Connector for Python Version: 3.17.1, Python Version: 3.13.7, Platform: Windows-11-10.0.26100-SP0
2025-08-22 10:11:43 - INFO - Connecting to GLOBAL Snowflake domain
2025-08-22 10:11:43 - WARNING - Retrying (Retry(total=0, connect=None, read=None, redirect=None, status=None)) after connection broken by 'NewConnectionError('<snowflake.connector.vendored.urllib3.connection.HTTPConnection object at 0x0000015A41AEED50>: Failed to establish a new connection: [Errno 11001] getaddrinfo failed')': /
2025-08-22 10:11:43 - WARNING - Retrying (Retry(total=0, connect=None, read=None, redirect=None, status=None)) after connection broken by 'NewConnectionError('<snowflake.connector.vendored.urllib3.connection.HTTPConnection object at 0x0000015A4198F6F0>: Failed to establish a new connection: [Errno 11001] getaddrinfo failed')': /computeMetadata/v1/instance/service-accounts/default/email
2025-08-22 10:11:43 - WARNING - Retrying (Retry(total=0, connect=None, read=None, redirect=None, status=None)) after connection broken by 'ConnectTimeoutError(<snowflake.connector.vendored.urllib3.connection.HTTPConnection object at 0x0000015A41AEA510>, 'Connection to 169.254.169.254 timed out. (connect timeout=0.2)')': /metadata/identity/oauth2/token?api-version=2018-02-01&resource=https://management.azure.com
2025-08-22 10:11:43 - WARNING - Retrying (Retry(total=0, connect=None, read=None, redirect=None, status=None)) after connection broken by 'ConnectTimeoutError(<snowflake.connector.vendored.urllib3.connection.HTTPConnection object at 0x0000015A41AEF110>, 'Connection to 169.254.169.254 timed out. (connect timeout=0.2)')': /metadata/instance?api-version=2021-02-01
2025-08-22 10:11:54 - INFO - Uploaded 4225 rows to 'customer_churn' in Snowflake.
2025-08-22 10:11:54 - INFO - customer churn data ingested to snowflake successfully.
2025-08-22 10:15:51 - INFO - Starting data ingestion process...Into snowflake
2025-08-22 10:15:51 - INFO - customer churn data read from csv successfully.
2025-08-22 10:15:51 - INFO - Data shape: (4225, 52)
2025-08-22 10:15:51 - INFO - Data columns: ['Age', 'Avg Monthly GB Download', 'Avg Monthly Long Distance Charges', 'Churn', 'Churn Category', 'Churn Reason', 'Churn Score', 'City', 'CLTV', 'Contract', 'Country', 'Customer ID', 'Customer Status', 'Dependents', 'Device Protection Plan', 'Gender', 'Internet Service', 'Internet Type', 'Lat Long', 'Latitude', 'Longitude', 'Married', 'Monthly Charge', 'Multiple Lines', 'Number of Dependents', 'Number of Referrals', 'Offer', 'Online Backup', 'Online Security', 'Paperless Billing', 'Partner', 'Payment Method', 'Phone Service', 'Population', 'Premium Tech Support', 'Quarter', 'Referred a Friend', 'Satisfaction Score', 'Senior Citizen', 'State', 'Streaming Movies', 'Streaming Music', 'Streaming TV', 'Tenure in Months', 'Total Charges', 'Total Extra Data Charges', 'Total Long Distance Charges', 'Total Refunds', 'Total Revenue', 'Under 30', 'Unlimited Data', 'Zip Code']
2025-08-22 10:15:51 - INFO - establishing connection to snowflake
2025-08-22 10:15:51 - INFO - Snowflake Connector for Python Version: 3.17.1, Python Version: 3.13.7, Platform: Windows-11-10.0.26100-SP0
2025-08-22 10:15:51 - INFO - Connecting to GLOBAL Snowflake domain
2025-08-22 10:15:51 - WARNING - Retrying (Retry(total=0, connect=None, read=None, redirect=None, status=None)) after connection broken by 'NewConnectionError('<snowflake.connector.vendored.urllib3.connection.HTTPConnection object at 0x000001FA75F5EC10>: Failed to establish a new connection: [Errno 11001] getaddrinfo failed')': /
2025-08-22 10:15:51 - WARNING - Retrying (Retry(total=0, connect=None, read=None, redirect=None, status=None)) after connection broken by 'NewConnectionError('<snowflake.connector.vendored.urllib3.connection.HTTPConnection object at 0x000001FA75DEF6F0>: Failed to establish a new connection: [Errno 11001] getaddrinfo failed')': /computeMetadata/v1/instance/service-accounts/default/email
2025-08-22 10:15:51 - WARNING - Retrying (Retry(total=0, connect=None, read=None, redirect=None, status=None)) after connection broken by 'ConnectTimeoutError(<snowflake.connector.vendored.urllib3.connection.HTTPConnection object at 0x000001FA75F56510>, 'Connection to 169.254.169.254 timed out. (connect timeout=0.2)')': /metadata/instance?api-version=2021-02-01
2025-08-22 10:15:51 - WARNING - Retrying (Retry(total=0, connect=None, read=None, redirect=None, status=None)) after connection broken by 'ConnectTimeoutError(<snowflake.connector.vendored.urllib3.connection.HTTPConnection object at 0x000001FA75F5F110>, 'Connection to 169.254.169.254 timed out. (connect timeout=0.2)')': /metadata/identity/oauth2/token?api-version=2018-02-01&resource=https://management.azure.com
2025-08-22 10:15:54 - INFO - Connection to Snowflake established successfully.
2025-08-22 10:15:54 - INFO - Uploading data to Snowflake...
2025-08-22 10:15:59 - INFO - Uploaded 4225 rows to 'customer_churn' in Snowflake.
2025-08-22 10:16:00 - INFO - Connection to Snowflake closed.
2025-08-22 10:16:00 - INFO - customer churn data ingested to snowflake successfully.
2025-08-22 22:26:54 - INFO - Starting data ingestion process...Into snowflake
2025-08-22 22:26:54 - INFO - customer churn data read from csv successfully.
2025-08-22 22:26:54 - INFO - Data shape: (4225, 52)
2025-08-22 22:26:54 - INFO - Data columns: ['Age', 'Avg Monthly GB Download', 'Avg Monthly Long Distance Charges', 'Churn', 'Churn Category', 'Churn Reason', 'Churn Score', 'City', 'CLTV', 'Contract', 'Country', 'Customer ID', 'Customer Status', 'Dependents', 'Device Protection Plan', 'Gender', 'Internet Service', 'Internet Type', 'Lat Long', 'Latitude', 'Longitude', 'Married', 'Monthly Charge', 'Multiple Lines', 'Number of Dependents', 'Number of Referrals', 'Offer', 'Online Backup', 'Online Security', 'Paperless Billing', 'Partner', 'Payment Method', 'Phone Service', 'Population', 'Premium Tech Support', 'Quarter', 'Referred a Friend', 'Satisfaction Score', 'Senior Citizen', 'State', 'Streaming Movies', 'Streaming Music', 'Streaming TV', 'Tenure in Months', 'Total Charges', 'Total Extra Data Charges', 'Total Long Distance Charges', 'Total Refunds', 'Total Revenue', 'Under 30', 'Unlimited Data', 'Zip Code']
2025-08-22 22:26:54 - INFO - establishing connection to snowflake
2025-08-22 22:26:54 - INFO - Snowflake Connector for Python Version: 3.17.1, Python Version: 3.13.7, Platform: Windows-11-10.0.26100-SP0
2025-08-22 22:26:54 - INFO - Connecting to GLOBAL Snowflake domain
2025-08-22 22:26:54 - WARNING - Retrying (Retry(total=0, connect=None, read=None, redirect=None, status=None)) after connection broken by 'NewConnectionError('<snowflake.connector.vendored.urllib3.connection.HTTPConnection object at 0x0000025EEB9F2510>: Failed to establish a new connection: [Errno 11001] getaddrinfo failed')': /
2025-08-22 22:26:54 - WARNING - Retrying (Retry(total=0, connect=None, read=None, redirect=None, status=None)) after connection broken by 'NewConnectionError('<snowflake.connector.vendored.urllib3.connection.HTTPConnection object at 0x0000025EEB9E6FD0>: Failed to establish a new connection: [Errno 11001] getaddrinfo failed')': /computeMetadata/v1/instance/service-accounts/default/email
2025-08-22 22:26:55 - WARNING - Retrying (Retry(total=0, connect=None, read=None, redirect=None, status=None)) after connection broken by 'ConnectTimeoutError(<snowflake.connector.vendored.urllib3.connection.HTTPConnection object at 0x0000025EEB9E7110>, 'Connection to 169.254.169.254 timed out. (connect timeout=0.2)')': /metadata/identity/oauth2/token?api-version=2018-02-01&resource=https://management.azure.com
2025-08-22 22:26:55 - WARNING - Retrying (Retry(total=0, connect=None, read=None, redirect=None, status=None)) after connection broken by 'ConnectTimeoutError(<snowflake.connector.vendored.urllib3.connection.HTTPConnection object at 0x0000025EEB88F6F0>, 'Connection to 169.254.169.254 timed out. (connect timeout=0.2)')': /metadata/instance?api-version=2021-02-01
2025-08-22 22:26:57 - INFO - Connection to Snowflake established successfully.
2025-08-22 22:26:57 - INFO - Uploading data to Snowflake...
2025-08-22 22:27:04 - INFO - Uploaded 4225 rows to 'customer_churn' in Snowflake.
2025-08-22 22:27:04 - INFO - Connection to Snowflake closed.
2025-08-22 22:27:04 - INFO - customer churn data ingested to snowflake successfully.
2025-08-22 23:25:43 - INFO - Starting data ingestion process...Into snowflake
2025-08-22 23:25:43 - INFO - customer churn data read from csv successfully.
2025-08-22 23:25:43 - INFO - Data shape: (4225, 52)
2025-08-22 23:25:43 - INFO - Data columns: ['Age', 'Avg Monthly GB Download', 'Avg Monthly Long Distance Charges', 'Churn', 'Churn Category', 'Churn Reason', 'Churn Score', 'City', 'CLTV', 'Contract', 'Country', 'Customer ID', 'Customer Status', 'Dependents', 'Device Protection Plan', 'Gender', 'Internet Service', 'Internet Type', 'Lat Long', 'Latitude', 'Longitude', 'Married', 'Monthly Charge', 'Multiple Lines', 'Number of Dependents', 'Number of Referrals', 'Offer', 'Online Backup', 'Online Security', 'Paperless Billing', 'Partner', 'Payment Method', 'Phone Service', 'Population', 'Premium Tech Support', 'Quarter', 'Referred a Friend', 'Satisfaction Score', 'Senior Citizen', 'State', 'Streaming Movies', 'Streaming Music', 'Streaming TV', 'Tenure in Months', 'Total Charges', 'Total Extra Data Charges', 'Total Long Distance Charges', 'Total Refunds', 'Total Revenue', 'Under 30', 'Unlimited Data', 'Zip Code']
2025-08-22 23:25:43 - INFO - establishing connection to snowflake
2025-08-22 23:25:43 - INFO - Snowflake Connector for Python Version: 3.17.1, Python Version: 3.13.7, Platform: Windows-11-10.0.26100-SP0
2025-08-22 23:25:43 - INFO - Connecting to GLOBAL Snowflake domain
2025-08-22 23:25:44 - WARNING - Retrying (Retry(total=0, connect=None, read=None, redirect=None, status=None)) after connection broken by 'NewConnectionError('<snowflake.connector.vendored.urllib3.connection.HTTPConnection object at 0x00000277A16DAD50>: Failed to establish a new connection: [Errno 11001] getaddrinfo failed')': /
2025-08-22 23:25:44 - WARNING - Retrying (Retry(total=0, connect=None, read=None, redirect=None, status=None)) after connection broken by 'NewConnectionError('<snowflake.connector.vendored.urllib3.connection.HTTPConnection object at 0x00000277A158F820>: Failed to establish a new connection: [Errno 11001] getaddrinfo failed')': /computeMetadata/v1/instance/service-accounts/default/email
2025-08-22 23:25:44 - WARNING - Retrying (Retry(total=0, connect=None, read=None, redirect=None, status=None)) after connection broken by 'ConnectTimeoutError(<snowflake.connector.vendored.urllib3.connection.HTTPConnection object at 0x00000277A16E23C0>, 'Connection to 169.254.169.254 timed out. (connect timeout=0.2)')': /metadata/instance?api-version=2021-02-01
2025-08-22 23:25:44 - WARNING - Retrying (Retry(total=0, connect=None, read=None, redirect=None, status=None)) after connection broken by 'ConnectTimeoutError(<snowflake.connector.vendored.urllib3.connection.HTTPConnection object at 0x00000277A16DB110>, 'Connection to 169.254.169.254 timed out. (connect timeout=0.2)')': /metadata/identity/oauth2/token?api-version=2018-02-01&resource=https://management.azure.com
2025-08-22 23:25:47 - INFO - Connection to Snowflake established successfully.
2025-08-22 23:25:47 - INFO - Uploading data to Snowflake...
2025-08-22 23:25:56 - INFO - Uploaded 4225 rows to 'customer_churn' in Snowflake.
2025-08-22 23:25:56 - INFO - Connection to Snowflake closed.
2025-08-22 23:25:56 - INFO - customer churn data ingested to snowflake successfully.
2025-08-22 23:30:32 - INFO - Starting data ingestion process...Into snowflake
2025-08-22 23:30:32 - INFO - customer churn data read from csv successfully.
2025-08-22 23:30:32 - INFO - Data shape: (4225, 52)
2025-08-22 23:30:32 - INFO - Data columns: ['Age', 'Avg Monthly GB Download', 'Avg Monthly Long Distance Charges', 'Churn', 'Churn Category', 'Churn Reason', 'Churn Score', 'City', 'CLTV', 'Contract', 'Country', 'Customer ID', 'Customer Status', 'Dependents', 'Device Protection Plan', 'Gender', 'Internet Service', 'Internet Type', 'Lat Long', 'Latitude', 'Longitude', 'Married', 'Monthly Charge', 'Multiple Lines', 'Number of Dependents', 'Number of Referrals', 'Offer', 'Online Backup', 'Online Security', 'Paperless Billing', 'Partner', 'Payment Method', 'Phone Service', 'Population', 'Premium Tech Support', 'Quarter', 'Referred a Friend', 'Satisfaction Score', 'Senior Citizen', 'State', 'Streaming Movies', 'Streaming Music', 'Streaming TV', 'Tenure in Months', 'Total Charges', 'Total Extra Data Charges', 'Total Long Distance Charges', 'Total Refunds', 'Total Revenue', 'Under 30', 'Unlimited Data', 'Zip Code']
2025-08-22 23:30:32 - INFO - establishing connection to snowflake
2025-08-22 23:30:32 - INFO - Snowflake Connector for Python Version: 3.17.1, Python Version: 3.13.7, Platform: Windows-11-10.0.26100-SP0
2025-08-22 23:30:32 - INFO - Connecting to GLOBAL Snowflake domain
2025-08-22 23:30:32 - WARNING - Retrying (Retry(total=0, connect=None, read=None, redirect=None, status=None)) after connection broken by 'NewConnectionError('<snowflake.connector.vendored.urllib3.connection.HTTPConnection object at 0x000001D3248D7250>: Failed to establish a new connection: [Errno 11001] getaddrinfo failed')': /
2025-08-22 23:30:32 - WARNING - Retrying (Retry(total=0, connect=None, read=None, redirect=None, status=None)) after connection broken by 'NewConnectionError('<snowflake.connector.vendored.urllib3.connection.HTTPConnection object at 0x000001D32478F6F0>: Failed to establish a new connection: [Errno 11001] getaddrinfo failed')': /computeMetadata/v1/instance/service-accounts/default/email
2025-08-22 23:30:33 - WARNING - Retrying (Retry(total=0, connect=None, read=None, redirect=None, status=None)) after connection broken by 'ConnectTimeoutError(<snowflake.connector.vendored.urllib3.connection.HTTPConnection object at 0x000001D3248E23C0>, 'Connection to 169.254.169.254 timed out. (connect timeout=0.2)')': /metadata/instance?api-version=2021-02-01
2025-08-22 23:30:33 - WARNING - Retrying (Retry(total=0, connect=None, read=None, redirect=None, status=None)) after connection broken by 'ConnectTimeoutError(<snowflake.connector.vendored.urllib3.connection.HTTPConnection object at 0x000001D3248D6E90>, 'Connection to 169.254.169.254 timed out. (connect timeout=0.2)')': /metadata/identity/oauth2/token?api-version=2018-02-01&resource=https://management.azure.com
2025-08-22 23:30:36 - INFO - Connection to Snowflake established successfully.
2025-08-22 23:30:36 - INFO - Uploading data to Snowflake...
2025-08-22 23:30:41 - INFO - Uploaded 4225 rows to 'customer_churn' in Snowflake.
2025-08-22 23:30:41 - INFO - Connection to Snowflake closed.
2025-08-22 23:30:41 - INFO - customer churn data ingested to snowflake successfully.
2025-08-22 23:38:41 - INFO - Starting data ingestion process...Into snowflake
2025-08-22 23:38:41 - INFO - customer churn data read from csv successfully.
2025-08-22 23:38:41 - INFO - Data shape: (4225, 52)
2025-08-22 23:38:41 - INFO - Data columns: ['Age', 'Avg Monthly GB Download', 'Avg Monthly Long Distance Charges', 'Churn', 'Churn Category', 'Churn Reason', 'Churn Score', 'City', 'CLTV', 'Contract', 'Country', 'Customer ID', 'Customer Status', 'Dependents', 'Device Protection Plan', 'Gender', 'Internet Service', 'Internet Type', 'Lat Long', 'Latitude', 'Longitude', 'Married', 'Monthly Charge', 'Multiple Lines', 'Number of Dependents', 'Number of Referrals', 'Offer', 'Online Backup', 'Online Security', 'Paperless Billing', 'Partner', 'Payment Method', 'Phone Service', 'Population', 'Premium Tech Support', 'Quarter', 'Referred a Friend', 'Satisfaction Score', 'Senior Citizen', 'State', 'Streaming Movies', 'Streaming Music', 'Streaming TV', 'Tenure in Months', 'Total Charges', 'Total Extra Data Charges', 'Total Long Distance Charges', 'Total Refunds', 'Total Revenue', 'Under 30', 'Unlimited Data', 'Zip Code']
2025-08-22 23:38:41 - INFO - establishing connection to snowflake
2025-08-22 23:38:41 - INFO - Snowflake Connector for Python Version: 3.17.1, Python Version: 3.13.7, Platform: Windows-11-10.0.26100-SP0
2025-08-22 23:38:41 - INFO - Connecting to GLOBAL Snowflake domain
2025-08-22 23:38:41 - WARNING - Retrying (Retry(total=0, connect=None, read=None, redirect=None, status=None)) after connection broken by 'NewConnectionError('<snowflake.connector.vendored.urllib3.connection.HTTPConnection object at 0x00000126D6CF7250>: Failed to establish a new connection: [Errno 11001] getaddrinfo failed')': /computeMetadata/v1/instance/service-accounts/default/email
2025-08-22 23:38:41 - WARNING - Retrying (Retry(total=0, connect=None, read=None, redirect=None, status=None)) after connection broken by 'NewConnectionError('<snowflake.connector.vendored.urllib3.connection.HTTPConnection object at 0x00000126D6CFE3C0>: Failed to establish a new connection: [Errno 11001] getaddrinfo failed')': /
2025-08-22 23:38:41 - WARNING - Retrying (Retry(total=0, connect=None, read=None, redirect=None, status=None)) after connection broken by 'ConnectTimeoutError(<snowflake.connector.vendored.urllib3.connection.HTTPConnection object at 0x00000126D6CF6E90>, 'Connection to 169.254.169.254 timed out. (connect timeout=0.2)')': /metadata/instance?api-version=2021-02-01
2025-08-22 23:38:41 - WARNING - Retrying (Retry(total=0, connect=None, read=None, redirect=None, status=None)) after connection broken by 'ConnectTimeoutError(<snowflake.connector.vendored.urllib3.connection.HTTPConnection object at 0x00000126D6B8F6F0>, 'Connection to 169.254.169.254 timed out. (connect timeout=0.2)')': /metadata/identity/oauth2/token?api-version=2018-02-01&resource=https://management.azure.com
2025-08-22 23:38:44 - INFO - Connection to Snowflake established successfully.
2025-08-22 23:38:44 - INFO - Uploading data to Snowflake...
2025-08-22 23:38:47 - INFO - Uploaded 4225 rows to 'customer_churn' in Snowflake.
2025-08-22 23:38:47 - INFO - Connection to Snowflake closed.
2025-08-22 23:38:47 - INFO - customer churn data ingested to snowflake successfully.
2025-08-23 00:10:05 - INFO - Starting data ingestion process...Into snowflake
2025-08-23 00:10:05 - INFO - customer churn data read from csv successfully.
2025-08-23 00:10:05 - INFO - Data shape: (3600, 52)
2025-08-23 00:10:05 - INFO - Data columns: ['Age', 'Avg Monthly GB Download', 'Avg Monthly Long Distance Charges', 'Churn', 'Churn Category', 'Churn Reason', 'Churn Score', 'City', 'CLTV', 'Contract', 'Country', 'Customer ID', 'Customer Status', 'Dependents', 'Device Protection Plan', 'Gender', 'Internet Service', 'Internet Type', 'Lat Long', 'Latitude', 'Longitude', 'Married', 'Monthly Charge', 'Multiple Lines', 'Number of Dependents', 'Number of Referrals', 'Offer', 'Online Backup', 'Online Security', 'Paperless Billing', 'Partner', 'Payment Method', 'Phone Service', 'Population', 'Premium Tech Support', 'Quarter', 'Referred a Friend', 'Satisfaction Score', 'Senior Citizen', 'State', 'Streaming Movies', 'Streaming Music', 'Streaming TV', 'Tenure in Months', 'Total Charges', 'Total Extra Data Charges', 'Total Long Distance Charges', 'Total Refunds', 'Total Revenue', 'Under 30', 'Unlimited Data', 'Zip Code']
2025-08-23 00:10:05 - INFO - establishing connection to snowflake
2025-08-23 00:10:05 - INFO - Snowflake Connector for Python Version: 3.17.1, Python Version: 3.13.7, Platform: Windows-11-10.0.26100-SP0
2025-08-23 00:10:05 - INFO - Connecting to GLOBAL Snowflake domain
2025-08-23 00:10:06 - WARNING - Retrying (Retry(total=0, connect=None, read=None, redirect=None, status=None)) after connection broken by 'NewConnectionError('<snowflake.connector.vendored.urllib3.connection.HTTPConnection object at 0x0000016B2ECCE3C0>: Failed to establish a new connection: [Errno 11001] getaddrinfo failed')': /computeMetadata/v1/instance/service-accounts/default/email
2025-08-23 00:10:06 - WARNING - Retrying (Retry(total=0, connect=None, read=None, redirect=None, status=None)) after connection broken by 'NewConnectionError('<snowflake.connector.vendored.urllib3.connection.HTTPConnection object at 0x0000016B2ECBF390>: Failed to establish a new connection: [Errno 11001] getaddrinfo failed')': /
2025-08-23 00:10:06 - WARNING - Retrying (Retry(total=0, connect=None, read=None, redirect=None, status=None)) after connection broken by 'ConnectTimeoutError(<snowflake.connector.vendored.urllib3.connection.HTTPConnection object at 0x0000016B2ECBEFD0>, 'Connection to 169.254.169.254 timed out. (connect timeout=0.2)')': /metadata/instance?api-version=2021-02-01
2025-08-23 00:10:06 - WARNING - Retrying (Retry(total=0, connect=None, read=None, redirect=None, status=None)) after connection broken by 'ConnectTimeoutError(<snowflake.connector.vendored.urllib3.connection.HTTPConnection object at 0x0000016B2EB8F6F0>, 'Connection to 169.254.169.254 timed out. (connect timeout=0.2)')': /metadata/identity/oauth2/token?api-version=2018-02-01&resource=https://management.azure.com
2025-08-23 00:10:09 - INFO - Connection to Snowflake established successfully.
2025-08-23 00:10:09 - INFO - Uploading data to Snowflake...
2025-08-23 00:10:14 - INFO - Uploaded 3600 rows to 'customer_churn' in Snowflake.
2025-08-23 00:10:14 - INFO - Connection to Snowflake closed.
2025-08-23 00:10:14 - INFO - customer churn data ingested to snowflake successfully.
2025-08-23 00:13:05 - INFO - Starting data ingestion process...Into snowflake
2025-08-23 00:13:05 - INFO - customer churn data read from csv successfully.
2025-08-23 00:13:05 - INFO - Data shape: (3600, 52)
2025-08-23 00:13:05 - INFO - Data columns: ['Age', 'Avg Monthly GB Download', 'Avg Monthly Long Distance Charges', 'Churn', 'Churn Category', 'Churn Reason', 'Churn Score', 'City', 'CLTV', 'Contract', 'Country', 'Customer ID', 'Customer Status', 'Dependents', 'Device Protection Plan', 'Gender', 'Internet Service', 'Internet Type', 'Lat Long', 'Latitude', 'Longitude', 'Married', 'Monthly Charge', 'Multiple Lines', 'Number of Dependents', 'Number of Referrals', 'Offer', 'Online Backup', 'Online Security', 'Paperless Billing', 'Partner', 'Payment Method', 'Phone Service', 'Population', 'Premium Tech Support', 'Quarter', 'Referred a Friend', 'Satisfaction Score', 'Senior Citizen', 'State', 'Streaming Movies', 'Streaming Music', 'Streaming TV', 'Tenure in Months', 'Total Charges', 'Total Extra Data Charges', 'Total Long Distance Charges', 'Total Refunds', 'Total Revenue', 'Under 30', 'Unlimited Data', 'Zip Code']
2025-08-23 00:13:05 - INFO - establishing connection to snowflake
2025-08-23 00:13:05 - INFO - Snowflake Connector for Python Version: 3.17.1, Python Version: 3.13.7, Platform: Windows-11-10.0.26100-SP0
2025-08-23 00:13:05 - INFO - Connecting to GLOBAL Snowflake domain
2025-08-23 00:13:06 - WARNING - Retrying (Retry(total=0, connect=None, read=None, redirect=None, status=None)) after connection broken by 'NewConnectionError('<snowflake.connector.vendored.urllib3.connection.HTTPConnection object at 0x000002BA230CF250>: Failed to establish a new connection: [Errno 11001] getaddrinfo failed')': /
2025-08-23 00:13:06 - WARNING - Retrying (Retry(total=0, connect=None, read=None, redirect=None, status=None)) after connection broken by 'NewConnectionError('<snowflake.connector.vendored.urllib3.connection.HTTPConnection object at 0x000002BA20F0F820>: Failed to establish a new connection: [Errno 11001] getaddrinfo failed')': /computeMetadata/v1/instance/service-accounts/default/email
2025-08-23 00:13:06 - WARNING - Retrying (Retry(total=0, connect=None, read=None, redirect=None, status=None)) after connection broken by 'ConnectTimeoutError(<snowflake.connector.vendored.urllib3.connection.HTTPConnection object at 0x000002BA230CEE90>, 'Connection to 169.254.169.254 timed out. (connect timeout=0.2)')': /metadata/identity/oauth2/token?api-version=2018-02-01&resource=https://management.azure.com
2025-08-23 00:13:06 - WARNING - Retrying (Retry(total=0, connect=None, read=None, redirect=None, status=None)) after connection broken by 'ConnectTimeoutError(<snowflake.connector.vendored.urllib3.connection.HTTPConnection object at 0x000002BA230D63C0>, 'Connection to 169.254.169.254 timed out. (connect timeout=0.2)')': /metadata/instance?api-version=2021-02-01
2025-08-23 00:13:08 - INFO - Connection to Snowflake established successfully.
2025-08-23 00:13:08 - INFO - Uploading data to Snowflake...
2025-08-23 00:13:11 - INFO - Uploaded 3600 rows to 'customer_churn' in Snowflake.
2025-08-23 00:13:11 - INFO - Connection to Snowflake closed.
2025-08-23 00:13:11 - INFO - customer churn data ingested to snowflake successfully.
2025-08-23 13:29:25 - INFO - Starting data ingestion process...Into snowflake
2025-08-23 13:29:25 - INFO - customer churn data read from csv successfully.
2025-08-23 13:29:25 - INFO - Data shape: (4225, 52)
2025-08-23 13:29:25 - INFO - Data columns: ['Age', 'Avg Monthly GB Download', 'Avg Monthly Long Distance Charges', 'Churn', 'Churn Category', 'Churn Reason', 'Churn Score', 'City', 'CLTV', 'Contract', 'Country', 'Customer ID', 'Customer Status', 'Dependents', 'Device Protection Plan', 'Gender', 'Internet Service', 'Internet Type', 'Lat Long', 'Latitude', 'Longitude', 'Married', 'Monthly Charge', 'Multiple Lines', 'Number of Dependents', 'Number of Referrals', 'Offer', 'Online Backup', 'Online Security', 'Paperless Billing', 'Partner', 'Payment Method', 'Phone Service', 'Population', 'Premium Tech Support', 'Quarter', 'Referred a Friend', 'Satisfaction Score', 'Senior Citizen', 'State', 'Streaming Movies', 'Streaming Music', 'Streaming TV', 'Tenure in Months', 'Total Charges', 'Total Extra Data Charges', 'Total Long Distance Charges', 'Total Refunds', 'Total Revenue', 'Under 30', 'Unlimited Data', 'Zip Code']
2025-08-23 13:29:25 - INFO - establishing connection to snowflake
2025-08-23 13:29:25 - INFO - Snowflake Connector for Python Version: 3.17.1, Python Version: 3.13.7, Platform: Windows-11-10.0.26100-SP0
2025-08-23 13:29:25 - INFO - Connecting to GLOBAL Snowflake domain
2025-08-23 13:29:26 - WARNING - Retrying (Retry(total=0, connect=None, read=None, redirect=None, status=None)) after connection broken by 'NewConnectionError('<snowflake.connector.vendored.urllib3.connection.HTTPConnection object at 0x0000028A2BD323C0>: Failed to establish a new connection: [Errno 11001] getaddrinfo failed')': /computeMetadata/v1/instance/service-accounts/default/email
2025-08-23 13:29:26 - WARNING - Retrying (Retry(total=0, connect=None, read=None, redirect=None, status=None)) after connection broken by 'NewConnectionError('<snowflake.connector.vendored.urllib3.connection.HTTPConnection object at 0x0000028A2BBBF6F0>: Failed to establish a new connection: [Errno 11001] getaddrinfo failed')': /
2025-08-23 13:29:26 - WARNING - Retrying (Retry(total=0, connect=None, read=None, redirect=None, status=None)) after connection broken by 'ConnectTimeoutError(<snowflake.connector.vendored.urllib3.connection.HTTPConnection object at 0x0000028A2BD26E90>, 'Connection to 169.254.169.254 timed out. (connect timeout=0.2)')': /metadata/instance?api-version=2021-02-01
2025-08-23 13:29:26 - WARNING - Retrying (Retry(total=0, connect=None, read=None, redirect=None, status=None)) after connection broken by 'ConnectTimeoutError(<snowflake.connector.vendored.urllib3.connection.HTTPConnection object at 0x0000028A2BD27250>, 'Connection to 169.254.169.254 timed out. (connect timeout=0.2)')': /metadata/identity/oauth2/token?api-version=2018-02-01&resource=https://management.azure.com
2025-08-23 13:29:29 - INFO - Connection to Snowflake established successfully.
2025-08-23 13:29:29 - INFO - Uploading data to Snowflake...
2025-08-23 13:29:36 - INFO - Uploaded 4225 rows to 'customer_churn' in Snowflake.
2025-08-23 13:29:36 - INFO - Connection to Snowflake closed.
2025-08-23 13:29:36 - INFO - customer churn data ingested to snowflake successfully.
2025-08-23 13:33:47 - INFO - Starting data ingestion process...Into snowflake
2025-08-23 13:33:47 - INFO - customer churn data read from csv successfully.
2025-08-23 13:33:47 - INFO - Data shape: (4225, 52)
2025-08-23 13:33:47 - INFO - Data columns: ['Age', 'Avg Monthly GB Download', 'Avg Monthly Long Distance Charges', 'Churn', 'Churn Category', 'Churn Reason', 'Churn Score', 'City', 'CLTV', 'Contract', 'Country', 'Customer ID', 'Customer Status', 'Dependents', 'Device Protection Plan', 'Gender', 'Internet Service', 'Internet Type', 'Lat Long', 'Latitude', 'Longitude', 'Married', 'Monthly Charge', 'Multiple Lines', 'Number of Dependents', 'Number of Referrals', 'Offer', 'Online Backup', 'Online Security', 'Paperless Billing', 'Partner', 'Payment Method', 'Phone Service', 'Population', 'Premium Tech Support', 'Quarter', 'Referred a Friend', 'Satisfaction Score', 'Senior Citizen', 'State', 'Streaming Movies', 'Streaming Music', 'Streaming TV', 'Tenure in Months', 'Total Charges', 'Total Extra Data Charges', 'Total Long Distance Charges', 'Total Refunds', 'Total Revenue', 'Under 30', 'Unlimited Data', 'Zip Code']
2025-08-23 13:33:47 - INFO - establishing connection to snowflake
2025-08-23 13:33:47 - INFO - Snowflake Connector for Python Version: 3.17.1, Python Version: 3.13.7, Platform: Windows-11-10.0.26100-SP0
2025-08-23 13:33:47 - INFO - Connecting to GLOBAL Snowflake domain
2025-08-23 13:33:48 - WARNING - Retrying (Retry(total=0, connect=None, read=None, redirect=None, status=None)) after connection broken by 'NewConnectionError('<snowflake.connector.vendored.urllib3.connection.HTTPConnection object at 0x0000020B03AF3250>: Failed to establish a new connection: [Errno 11001] getaddrinfo failed')': /
2025-08-23 13:33:48 - WARNING - Retrying (Retry(total=0, connect=None, read=None, redirect=None, status=None)) after connection broken by 'NewConnectionError('<snowflake.connector.vendored.urllib3.connection.HTTPConnection object at 0x0000020B03B023C0>: Failed to establish a new connection: [Errno 11001] getaddrinfo failed')': /computeMetadata/v1/instance/service-accounts/default/email
2025-08-23 13:33:48 - WARNING - Retrying (Retry(total=0, connect=None, read=None, redirect=None, status=None)) after connection broken by 'ConnectTimeoutError(<snowflake.connector.vendored.urllib3.connection.HTTPConnection object at 0x0000020B0398F6F0>, 'Connection to 169.254.169.254 timed out. (connect timeout=0.2)')': /metadata/instance?api-version=2021-02-01
2025-08-23 13:33:48 - WARNING - Retrying (Retry(total=0, connect=None, read=None, redirect=None, status=None)) after connection broken by 'ConnectTimeoutError(<snowflake.connector.vendored.urllib3.connection.HTTPConnection object at 0x0000020B03AF2E90>, 'Connection to 169.254.169.254 timed out. (connect timeout=0.2)')': /metadata/identity/oauth2/token?api-version=2018-02-01&resource=https://management.azure.com
2025-08-23 13:33:51 - INFO - Connection to Snowflake established successfully.
2025-08-23 13:33:51 - INFO - Uploading data to Snowflake...
2025-08-23 13:33:53 - INFO - Uploaded 4225 rows to 'customer_churn' in Snowflake.
2025-08-23 13:33:53 - INFO - Connection to Snowflake closed.
2025-08-23 13:33:53 - INFO - customer churn data ingested to snowflake successfully.
